#VRML_SIM R2022b utf8
# license: Apache License 2.0
# license url: http://www.apache.org/licenses/LICENSE-2.0
# This is a proto file for Webots for the Nao
# Extracted from: /home/bee/irakaskuntza/robotica-social/ros/src/nao_webots/urdf/Nao.urdf

PROTO Nao [
  field  SFVec3f     translation     0 0 0
  field  SFRotation  rotation        0 0 1 0
  field  SFString    name            "Nao"  # Is `Robot.name`.
  field  SFString    controller      "void" # Is `Robot.controller`.
  field  MFString    controllerArgs  []     # Is `Robot.controllerArgs`.
  field  SFString    customData      ""     # Is `Robot.customData`.
  field  SFBool      supervisor      FALSE  # Is `Robot.supervisor`.
  field  SFBool      synchronization TRUE   # Is `Robot.synchronization`.
  field  SFBool      selfCollision   FALSE  # Is `Robot.selfCollision`.
  field  SFBool      staticBase      TRUE   # Defines if the robot base should be pinned to the static environment.
]
{
  Robot {
    translation IS translation
    rotation IS rotation
    controller IS controller
    controllerArgs IS controllerArgs
    customData IS customData
    supervisor IS supervisor
    synchronization IS synchronization
    selfCollision IS selfCollision
    children [
      Transform {
        translation 0.000000 0.000000 0.020000
        children [
          Shape {
            appearance PBRAppearance {
              baseColor 0.500000 0.500000 0.500000
              roughness 1.000000
              metalness 0
            }
            geometry Cylinder {
              radius 0.055
              height 0.11
            }
          }
        ]
      }
      Transform {
        translation 0.000000 0.055000 0.020000
        children [
          Shape {
            appearance PBRAppearance {
              baseColor 0.500000 0.500000 0.500000
              roughness 1.000000
              metalness 0
            }
            geometry Sphere {
              radius 0.055
            }
          }
        ]
      }
      Transform {
        translation 0.000000 -0.055000 0.020000
        children [
          Shape {
            appearance PBRAppearance {
              baseColor 0.500000 0.500000 0.500000
              roughness 1.000000
              metalness 0
            }
            geometry Sphere {
              radius 0.055
            }
          }
        ]
      }
      HingeJoint {
        jointParameters HingeJointParameters {
          axis 0.000000 0.707107 -0.707107
          anchor 0.000000 0.050000 -0.085000
        }
        device [
          RotationalMotor {
            name "base_link-solid"
            maxVelocity 4.16174
            minPosition -1.14529
            maxPosition 0.740718
            maxTorque 14.8
          }
          PositionSensor {
            name "base_link-solid_sensor"
          }
        ]
        endPoint Solid {
          translation 0.000000 0.050000 -0.085000
          children [
            Transform {
              translation -0.022000 0.000000 0.000000
              children [
                Shape {
                  appearance PBRAppearance {
                    baseColor 0.500000 0.500000 0.500000
                    roughness 1.000000
                    metalness 0
                  }
                  geometry Box {
                     size 0.080000 0.050000 0.050000
                  }
                }
              ]
            }
            HingeJoint {
              jointParameters HingeJointParameters {
                axis 0.000000 1.000000 0.000000
              }
              device [
                RotationalMotor {
                  name "LHipPitch"
                  maxVelocity 6.40239
                  minPosition -1.77378
                  maxPosition 0.48398
                  maxTorque 9.8
                }
                PositionSensor {
                  name "LHipPitch_sensor"
                }
              ]
              endPoint Solid {
                children [
                  Transform {
                    translation 0.000000 0.000000 -0.055000
                    rotation 0.000000 -1.000000 0.000000 0.383185
                    children [
                      Shape {
                        appearance PBRAppearance {
                          baseColor 0.500000 0.500000 0.500000
                          roughness 1.000000
                          metalness 0
                        }
                        geometry Box {
                           size 0.060000 0.080000 0.130000
                        }
                      }
                    ]
                  }
                  HingeJoint {
                    jointParameters HingeJointParameters {
                      axis 0.000000 1.000000 0.000000
                      anchor 0.000000 0.000000 -0.100000
                    }
                    device [
                      RotationalMotor {
                        name "LKneePitch"
                        maxVelocity 6.40239
                        minPosition -0.0923279
                        maxPosition 2.11255
                        maxTorque 9.8
                      }
                      PositionSensor {
                        name "LKneePitch_sensor"
                      }
                    ]
                    endPoint Solid {
                      translation 0.000000 0.000000 -0.100000
                      children [
                        Transform {
                          translation 0.010000 0.000000 -0.055000
                          rotation 0.000000 1.000000 0.000000 0.200000
                          children [
                            Shape {
                              appearance PBRAppearance {
                                baseColor 0.500000 0.500000 0.500000
                                roughness 1.000000
                                metalness 0
                              }
                              geometry Box {
                                 size 0.060000 0.080000 0.110000
                              }
                            }
                          ]
                        }
                        HingeJoint {
                          jointParameters HingeJointParameters {
                            axis 0.000000 1.000000 0.000000
                            anchor 0.000000 0.000000 -0.102900
                          }
                          device [
                            RotationalMotor {
                              name "solid_1-solid_3"
                              maxVelocity 6.40239
                              minPosition -1.18944
                              maxPosition 0.922581
                              maxTorque 9.8
                            }
                            PositionSensor {
                              name "solid_1-solid_3_sensor"
                            }
                          ]
                          endPoint Solid {
                            translation 0.000000 0.000000 -0.102900
                            children [
                              Transform {
                                translation 0.020000 0.007000 -0.025000
                                children [
                                  Shape {
                                    appearance PBRAppearance {
                                      baseColor 0.500000 0.500000 0.500000
                                      roughness 1.000000
                                      metalness 0
                                    }
                                    geometry Box {
                                       size 0.148000 0.090000 0.020000
                                    }
                                  }
                                ]
                              }
                              Solid {
                                translation 0.090000 -0.012000 -0.023000
                                children [
                                  Transform {
                                    translation 0.007500 0.000000 0.000000
                                    children [
                                      Shape {
                                        appearance PBRAppearance {
                                          baseColor 0.500000 0.500000 0.500000
                                          roughness 1.000000
                                          metalness 0
                                        }
                                        geometry Box {
                                           size 0.005000 0.025000 0.010000
                                        }
                                      }
                                    ]
                                  }
                                ]
                                name "LFoot/Bumper/Right"
                                boundingObject Transform {
                                  translation 0.007500 0.000000 0.000000
                                  children [
                                    Box {
                                       size 0.005000 0.025000 0.010000
                                    }
                                  ]
                                }
                                physics Physics {
                                }
                              }
                              Solid {
                                translation 0.090000 0.022000 -0.023000
                                children [
                                  Transform {
                                    translation 0.007500 0.000000 0.000000
                                    children [
                                      Shape {
                                        appearance PBRAppearance {
                                          baseColor 0.500000 0.500000 0.500000
                                          roughness 1.000000
                                          metalness 0
                                        }
                                        geometry Box {
                                           size 0.005000 0.025000 0.010000
                                        }
                                      }
                                    ]
                                  }
                                ]
                                name "LFoot/Bumper/Left"
                                boundingObject Transform {
                                  translation 0.007500 0.000000 0.000000
                                  children [
                                    Box {
                                       size 0.005000 0.025000 0.010000
                                    }
                                  ]
                                }
                                physics Physics {
                                }
                              }
                            ]
                            name "solid_3"
                            boundingObject Transform {
                              translation 0.020000 0.007000 -0.025000
                              children [
                                Box {
                                   size 0.148000 0.090000 0.020000
                                }
                              ]
                            }
                            physics Physics {
                            }
                          }
                        }
                      ]
                      name "solid_1"
                      boundingObject Transform {
                        translation 0.010000 0.000000 -0.055000
                        rotation 0.000000 1.000000 0.000000 0.200000
                        children [
                          Box {
                             size 0.060000 0.080000 0.110000
                          }
                        ]
                      }
                      physics Physics {
                      }
                    }
                  }
                ]
                name "solid_0"
                boundingObject Transform {
                  translation 0.000000 0.000000 -0.055000
                  rotation 0.000000 -1.000000 0.000000 0.383185
                  children [
                    Box {
                       size 0.060000 0.080000 0.130000
                    }
                  ]
                }
                physics Physics {
                }
              }
            }
          ]
          name "solid"
          boundingObject Transform {
            translation -0.022000 0.000000 0.000000
            children [
              Box {
                 size 0.080000 0.050000 0.050000
              }
            ]
          }
          physics Physics {
          }
        }
      }
      HingeJoint {
        jointParameters HingeJointParameters {
          axis 0.000000 0.707107 0.707107
          anchor 0.000000 -0.050000 -0.085000
        }
        device [
          RotationalMotor {
            name "base_link-solid_4"
            maxVelocity 4.16174
            minPosition -1.14529
            maxPosition 0.740718
            maxTorque 14.8
          }
          PositionSensor {
            name "base_link-solid_4_sensor"
          }
        ]
        endPoint Solid {
          translation 0.000000 -0.050000 -0.085000
          children [
            Transform {
              translation -0.022000 0.000000 0.000000
              children [
                Shape {
                  appearance PBRAppearance {
                    baseColor 0.500000 0.500000 0.500000
                    roughness 1.000000
                    metalness 0
                  }
                  geometry Box {
                     size 0.080000 0.050000 0.050000
                  }
                }
              ]
            }
            HingeJoint {
              jointParameters HingeJointParameters {
                axis 0.000000 1.000000 0.000000
              }
              device [
                RotationalMotor {
                  name "RHipPitch"
                  maxVelocity 6.40239
                  minPosition -1.77378
                  maxPosition 0.48398
                  maxTorque 9.8
                }
                PositionSensor {
                  name "RHipPitch_sensor"
                }
              ]
              endPoint Solid {
                children [
                  Transform {
                    translation 0.000000 0.000000 -0.055000
                    rotation 0.000000 -1.000000 0.000000 0.383185
                    children [
                      Shape {
                        appearance PBRAppearance {
                          baseColor 0.500000 0.500000 0.500000
                          roughness 1.000000
                          metalness 0
                        }
                        geometry Box {
                           size 0.060000 0.080000 0.130000
                        }
                      }
                    ]
                  }
                  HingeJoint {
                    jointParameters HingeJointParameters {
                      axis 0.000000 1.000000 0.000000
                      anchor 0.000000 0.000000 -0.100000
                    }
                    device [
                      RotationalMotor {
                        name "RKneePitch"
                        maxVelocity 6.40239
                        minPosition -0.0923279
                        maxPosition 2.11255
                        maxTorque 9.8
                      }
                      PositionSensor {
                        name "RKneePitch_sensor"
                      }
                    ]
                    endPoint Solid {
                      translation 0.000000 0.000000 -0.100000
                      children [
                        Transform {
                          translation 0.010000 0.000000 -0.055000
                          rotation 0.000000 1.000000 0.000000 0.200000
                          children [
                            Shape {
                              appearance PBRAppearance {
                                baseColor 0.500000 0.500000 0.500000
                                roughness 1.000000
                                metalness 0
                              }
                              geometry Box {
                                 size 0.060000 0.080000 0.110000
                              }
                            }
                          ]
                        }
                        HingeJoint {
                          jointParameters HingeJointParameters {
                            axis 0.000000 1.000000 0.000000
                            anchor 0.000000 0.000000 -0.102900
                          }
                          device [
                            RotationalMotor {
                              name "solid_6-solid_8"
                              maxVelocity 6.40239
                              minPosition -1.1863
                              maxPosition 0.932006
                              maxTorque 9.8
                            }
                            PositionSensor {
                              name "solid_6-solid_8_sensor"
                            }
                          ]
                          endPoint Solid {
                            translation 0.000000 0.000000 -0.102900
                            children [
                              Transform {
                                translation 0.020000 -0.007000 -0.025000
                                children [
                                  Shape {
                                    appearance PBRAppearance {
                                      baseColor 0.500000 0.500000 0.500000
                                      roughness 1.000000
                                      metalness 0
                                    }
                                    geometry Box {
                                       size 0.148000 0.090000 0.020000
                                    }
                                  }
                                ]
                              }
                              Solid {
                                translation 0.090000 0.012000 -0.023000
                                children [
                                  Transform {
                                    translation 0.007500 0.000000 0.000000
                                    children [
                                      Shape {
                                        appearance PBRAppearance {
                                          baseColor 0.500000 0.500000 0.500000
                                          roughness 1.000000
                                          metalness 0
                                        }
                                        geometry Box {
                                           size 0.005000 0.025000 0.010000
                                        }
                                      }
                                    ]
                                  }
                                ]
                                name "RFoot/Bumper/Left"
                                boundingObject Transform {
                                  translation 0.007500 0.000000 0.000000
                                  children [
                                    Box {
                                       size 0.005000 0.025000 0.010000
                                    }
                                  ]
                                }
                                physics Physics {
                                }
                              }
                              Solid {
                                translation 0.090000 -0.022000 -0.023000
                                children [
                                  Transform {
                                    translation 0.007500 0.000000 0.000000
                                    children [
                                      Shape {
                                        appearance PBRAppearance {
                                          baseColor 0.500000 0.500000 0.500000
                                          roughness 1.000000
                                          metalness 0
                                        }
                                        geometry Box {
                                           size 0.005000 0.025000 0.010000
                                        }
                                      }
                                    ]
                                  }
                                ]
                                name "RFoot/Bumper/Right"
                                boundingObject Transform {
                                  translation 0.007500 0.000000 0.000000
                                  children [
                                    Box {
                                       size 0.005000 0.025000 0.010000
                                    }
                                  ]
                                }
                                physics Physics {
                                }
                              }
                            ]
                            name "solid_8"
                            boundingObject Transform {
                              translation 0.020000 -0.007000 -0.025000
                              children [
                                Box {
                                   size 0.148000 0.090000 0.020000
                                }
                              ]
                            }
                            physics Physics {
                            }
                          }
                        }
                      ]
                      name "solid_6"
                      boundingObject Transform {
                        translation 0.010000 0.000000 -0.055000
                        rotation 0.000000 1.000000 0.000000 0.200000
                        children [
                          Box {
                             size 0.060000 0.080000 0.110000
                          }
                        ]
                      }
                      physics Physics {
                      }
                    }
                  }
                ]
                name "solid_5"
                boundingObject Transform {
                  translation 0.000000 0.000000 -0.055000
                  rotation 0.000000 -1.000000 0.000000 0.383185
                  children [
                    Box {
                       size 0.060000 0.080000 0.130000
                    }
                  ]
                }
                physics Physics {
                }
              }
            }
          ]
          name "solid_4"
          boundingObject Transform {
            translation -0.022000 0.000000 0.000000
            children [
              Box {
                 size 0.080000 0.050000 0.050000
              }
            ]
          }
          physics Physics {
          }
        }
      }
    ]
    name IS name
    boundingObject Group {
      children [
        Transform {
          translation 0.000000 0.000000 0.020000
          children [
            Cylinder {
              radius 0.055
              height 0.11
            }
          ]
        }
        Transform {
          translation 0.000000 0.055000 0.020000
          children [
            Sphere {
              radius 0.055
            }
          ]
        }
        Transform {
          translation 0.000000 -0.055000 0.020000
          children [
            Sphere {
              radius 0.055
            }
          ]
        }
      ]
    }
  }
}
